Workbook
Name Slicer_Country: #N/A
Name Slicer_Income_Level: #N/A
Name Slicer_Income_Level1: #N/A
Name Slicer_Income_Level2: #N/A
Name Slicer_Income_Level3: #N/A
Name Slicer_Income_Level4: #N/A
Name Slicer_Region: #N/A
Name Slicer_Region1: #N/A
Name Slicer_Region2: #N/A
Name Slicer_Region3: #N/A
Name Slicer_Region4: #N/A
Name Slicer_Year: #N/A
Name Slicer_Year1: #N/A
Name Slicer_Year2: #N/A
Name Slicer_Year3: #N/A

Sheet IncomeLevel_Cleaned
A1: Country Name | B1: Country Code | C1: 1960 | D1: 1961 | E1: 1962 | F1: 1963 | G1: 1964 | H1: 1965 | I1: 1966 | J1: 1967 | K1: 1968 | L1: 1969 | M1: 1970 | N1: 1971 | O1: 1972 | P1: 1973 | Q1: 1974 | R1: 1975 | S1: 1976 | T1: 1977 | U1: 1978 | V1: 1979 | W1: 1980 | X1: 1981 | Y1: 1982 | Z1: 1983 | AA1: 1984 | AB1: 1985 | AC1: 1986 | AD1: 1987 | AE1: 1988 | AF1: 1989 | AG1: 1990 | AH1: 1991 | AI1: 1992 | AJ1: 1993 | AK1: 1994 | AL1: 1995 | AM1: 1996 | AN1: 1997 | AO1: 1998 | AP1: 1999 | AQ1: 2000 | AR1: 2001 | AS1: 2002 | AT1: 2003 | AU1: 2004 | AV1: 2005 | AW1: 2006 | AX1: 2007 | AY1: 2008 | AZ1: 2009 | BA1: 2010 | BB1: 2011 | BC1: 2012 | BD1: 2013 | BE1: 2014 | BF1: 2015 | BG1: 2016 | BH1: 2017 | BI1: 2018 | BJ1: 2019 | BK1: 2020 | BL1: 2021 | BM1: 2022 | BN1: 2023 | BO1: 2024 | BP1: ABW | BQ1: Region | BR1: Income | BS1: Country
A2: Aruba | B2: ABW | C2: 64.049 | D2: 64.215 | E2: 64.602 | F2: 64.944 | G2: 65.303 | H2: 65.615 | I2: 66.126 | J2: 66.385 | K2: 66.744 | L2: 67.098 | M2: 67.44 | N2: 67.783 | O2: 68.335 | P2: 68.862 | Q2: 69.278 | R2: 69.564 | S2: 69.808 | T2: 70.054 | U2: 70.271 | V2: 70.507 | W2: 70.771 | X2: 71.344 | Y2: 71.485 | Z2: 71.606 | AA2: 71.711 | AB2: 71.792 | AC2: 71.831 | AD2: 72.448 | AE2: 72.519 | AF2: 72.531 | AG2: 72.546 | AH2: 72.592 | AI2: 72.717 | AJ2: 72.777 | AK2: 72.796 | AL2: 72.832 | AM2: 72.856 | AN2: 72.904 | AO2: 72.94 | AP2: 72.857 | AQ2: 72.939 | AR2: 73.044 | AS2: 73.135 | AT2: 73.236 | AU2: 73.223 | AV2: 73.415 | AW2: 73.498 | AX2: 73.642 | AY2: 73.783 | AZ2: 73.974 | BA2: 74.297 | BB2: 74.578 | BC2: 74.841 | BD2: 75.072 | BE2: 75.261 | BF2: 75.405 | BG2: 75.54 | BH2: 75.62 | BI2: 75.88 | BJ2: 76.019 | BK2: 75.406 | BL2: 73.655 | BM2: 76.226 | BN2: 76.353 | BO2: 76.5
A3: Africa Eastern and Southern | B3: AFE | C3: 44.169658 | D3: 44.468838 | E3: 44.87789 | F3: 45.160583 | G3: 45.535695 | H3: 45.770723 | I3: 45.765725 | J3: 46.440745 | K3: 46.738632 | L3: 46.977476 | M3: 47.248006 | N3: 47.464016 | O3: 47.166792 | P3: 47.746608 | Q3: 47.744328 | R3: 47.968548 | S3: 48.568138 | T3: 48.860725 | U3: 48.983917 | V3: 49.416988 | W3: 49.816713 | X3: 50.020493 | Y3: 50.290829 | Z3: 48.904096 | AA3: 48.997959 | AB3: 49.392902 | AC3: 50.009761 | AD3: 51.068943 | AE3: 50.876607 | AF3: 51.265874 | AG3: 51.096326 | AH3: 50.873244 | AI3: 50.715946 | AJ3: 51.073762 | AK3: 50.966589 | AL3: 51.482057 | AM3: 51.35319 | AN3: 51.570887 | AO3: 51.317955 | AP3: 51.807077 | AQ3: 52.557342 | AR3: 52.875536 | AS3: 53.206744 | AT3: 53.678305 | AU3: 54.192928 | AV3: 54.807681 | AW3: 55.693515 | AX3: 56.484353 | AY3: 57.240106 | AZ3: 58.095527 | BA3: 58.827279 | BB3: 59.200004 | BC3: 60.249512 | BD3: 60.89574 | BE3: 61.251436 | BF3: 61.713031 | BG3: 62.167981 | BH3: 62.591275 | BI3: 63.330691 | BJ3: 63.857261 | BK3: 63.766484 | BL3: 62.979999 | BM3: 64.487152 | BN3: 65.146228 | BO3: 65.34993 | BP3: AFE | BS3: Africa Eastern and Southern
A4: Afghanistan | B4: AFG | C4: 32.799 | D4: 33.291 | E4: 33.757 | F4: 34.201 | G4: 34.673 | H4: 35.124 | I4: 35.583 | J4: 36.042 | K4: 36.51 | L4: 36.979 | M4: 37.46 | N4: 37.932 | O4: 38.423 | P4: 38.951 | Q4: 39.469 | R4: 39.994 | S4: 40.518 | T4: 41.082 | U4: 40.086 | V4: 38.844 | W4: 39.258 | X4: 39.406 | Y4: 36.058 | Z4: 36.517 | AA4: 31.473 | AB4: 32.132 | AC4: 38.4 | AD4: 38.831 | AE4: 43.238 | AF4: 44.496 | AG4: 45.118 | AH4: 45.521 | AI4: 46.569 | AJ4: 51.021 | AK4: 50.969 | AL4: 52.103 | AM4: 52.83 | AN4: 53.212 | AO4: 52.487 | AP4: 54.532 | AQ4: 55.005 | AR4: 55.511 | AS4: 56.225 | AT4: 57.171 | AU4: 57.81 | AV4: 58.247 | AW4: 58.553 | AX4: 58.956 | AY4: 59.708 | AZ4: 60.248 | BA4: 60.702 | BB4: 61.25 | BC4: 61.735 | BD4: 62.188 | BE4: 62.26 | BF4: 62.27 | BG4: 62.646 | BH4: 62.406 | BI4: 62.443 | BJ4: 62.941 | BK4: 61.454 | BL4: 60.417 | BM4: 65.617 | BN4: 66.035 | BO4: 66.289 | BP4: AFG | BQ4: Middle East & North Africa | BR4: Low income | BS4: Afghanistan
A5: Africa Western and Central | B5: AFW | C5: 37.779636 | D5: 38.058973 | E5: 38.681792 | F5: 38.936918 | G5: 39.19458 | H5: 39.479784 | I5: 39.719265 | J5: 39.529359 | K5: 40.25889 | L5: 40.567814 | M5: 41.277939 | N5: 41.730102 | O5: 42.356132 | P5: 42.868104 | Q5: 43.437155 | R5: 43.967079 | S5: 44.75257 | T5: 45.362264 | U5: 45.876278 | V5: 46.328507 | W5: 46.696229 | X5: 47.075219 | Y5: 47.373942 | Z5: 47.619559 | AA5: 47.797646 | AB5: 47.944482 | AC5: 48.038163 | AD5: 48.139567 | AE5: 48.371525 | AF5: 48.496155 | AG5: 48.459467 | AH5: 48.531229 | AI5: 48.688726 | AJ5: 48.855051 | AK5: 48.859717 | AL5: 49.027301 | AM5: 49.11178 | AN5: 49.21897 | AO5: 49.45259 | AP5: 49.823913 | AQ5: 50.29817 | AR5: 50.677996 | AS5: 51.108247 | AT5: 51.578364 | AU5: 52.106342 | AV5: 52.55603 | AW5: 52.978931 | AX5: 53.482672 | AY5: 53.916483 | AZ5: 53.852486 | BA5: 54.603593 | BB5: 54.964195 | BC5: 55.292945 | BD5: 55.55511 | BE5: 55.69563 | BF5: 56.038519 | BG5: 56.392598 | BH5: 56.626622 | BI5: 57.037104 | BJ5: 57.149956 | BK5: 57.364736 | BL5: 57.362736 | BM5: 57.98785 | BN5: 58.85574 | BO5: 59.049811 | BP5: AFW | BS5: Africa Western and Central
A6: Angola | B6: AGO | C6: 37.933 | D6: 36.902 | E6: 37.168 | F6: 37.419 | G6: 37.704 | H6: 37.968 | I6: 38.258 | J6: 38.616 | K6: 38.968 | L6: 39.329 | M6: 39.688 | N6: 40.076 | O6: 40.469 | P6: 40.871 | Q6: 41.26 | R6: 40.817 | S6: 40.812 | T6: 41.215 | U6: 41.573 | V6: 41.913 | W6: 42.242 | X6: 42.556 | Y6: 42.857 | Z6: 41.972 | AA6: 42.245 | AB6: 42.495 | AC6: 42.739 | AD6: 40.786 | AE6: 41.471 | AF6: 41.698 | AG6: 41.854 | AH6: 43.812 | AI6: 42.267 | AJ6: 42.19 | AK6: 43.567 | AL6: 46.139 | AM6: 46.418 | AN6: 46.688 | AO6: 45.452 | AP6: 45.808 | AQ6: 46.501 | AR6: 47.032 | AS6: 47.874 | AT6: 50.218 | AU6: 51.123 | AV6: 52.13 | AW6: 52.965 | AX6: 54.2 | AY6: 55.281 | AZ6: 56.225 | BA6: 57.242 | BB6: 58.093 | BC6: 58.916 | BD6: 59.705 | BE6: 60.396 | BF6: 61.042 | BG6: 61.619 | BH6: 62.122 | BI6: 62.622 | BJ6: 63.051 | BK6: 63.116 | BL6: 62.958 | BM6: 64.246 | BN6: 64.617 | BO6: 64.805 | BP6: AGO | BQ6: Sub-Saharan Africa | BR6: Lower middle income | BS6: Angola
A7: Albania | B7: ALB | C7: 56.413 | D7: 57.488 | E7: 58.494 | F7: 59.479 | G7: 60.404 | H7: 61.273 | I7: 62.149 | J7: 62.976 | K7: 63.788 | L7: 64.538 | M7: 65.234 | N7: 65.896 | O7: 66.526 | P7: 67.107 | Q7: 67.633 | R7: 68.12 | S7: 68.57 | T7: 68.992 | U7: 69.367 | V7: 69.617 | W7: 69.903 | X7: 70.145 | Y7: 70.425 | Z7: 70.705 | AA7: 70.984 | AB7: 71.282 | AC7: 71.665 | AD7: 71.981 | AE7: 72.217 | AF7: 72.457 | AG7: 72.71 | AH7: 73.001 | AI7: 73.303 | AJ7: 73.638 | AK7: 73.837 | AL7: 74.022 | AM7: 74.113 | AN7: 73.383 | AO7: 74.357 | AP7: 74.568 | AQ7: 74.826 | AR7: 75.083 | AS7: 75.299 | AT7: 75.557 | AU7: 75.951 | AV7: 76.427 | AW7: 76.994 | AX7: 77.691 | AY7: 78.248 | AZ7: 78.509 | BA7: 78.414 | BB7: 78.303 | BC7: 78.084 | BD7: 77.995 | BE7: 78.029 | BF7: 78.358 | BG7: 78.643 | BH7: 78.9 | BI7: 79.238 | BJ7: 79.467 | BK7: 77.824 | BL7: 76.844 | BM7: 78.769 | BN7: 79.602 | BO7: 79.776 | BP7: ALB | BQ7: Europe & Central Asia | BR7: Upper middle income | BS7: Albania
A8: Andorra | B8: AND | C8: 72.094 | D8: 72.573 | E8: 72.993 | F8: 73.298 | G8: 73.624 | H8: 73.856 | I8: 74.02 | J8: 74.119 | K8: 74.22 | L8: 74.296 | M8: 74.452 | N8: 74.615 | O8: 74.864 | P8: 75.096 | Q8: 75.34 | R8: 75.567 | S8: 75.869 | T8: 76.154 | U8: 76.488 | V8: 76.819 | W8: 77.137 | X8: 77.391 | Y8: 77.617 | Z8: 77.787 | AA8: 77.916 | AB8: 78.006 | AC8: 78.107 | AD8: 78.189 | AE8: 78.364 | AF8: 78.557 | AG8: 78.961 | AH8: 79.346 | AI8: 79.794 | AJ8: 80.186 | AK8: 80.587 | AL8: 80.804 | AM8: 81.009 | AN8: 81.145 | AO8: 81.28 | AP8: 81.55 | AQ8: 81.863 | AR8: 82.162 | AS8: 82.448 | AT8: 82.718 | AU8: 82.815 | AV8: 83.086 | AW8: 83.374 | AX8: 83.632 | AY8: 83.855 | AZ8: 84.1 | BA8: 84.197 | BB8: 84.296 | BC8: 84.334 | BD8: 84.406 | BE8: 84.485 | BF8: 84.532 | BG8: 84.489 | BH8: 84.359 | BI8: 84.242 | BJ8: 84.098 | BK8: 79.418 | BL8: 82.331 | BM8: 84.016 | BN8: 84.041 | BO8: 84.188 | BP8: AND | BQ8: Europe & Central Asia | BR8: High income | BS8: Andorra
A9: Arab World | B9: ARB | C9: 44.794056 | D9: 45.545371 | E9: 45.993769 | F9: 46.979338 | G9: 47.570034 | H9: 48.117159 | I9: 48.625424 | J9: 49.092434 | K9: 49.657787 | L9: 50.148857 | M9: 50.692871 | N9: 51.318319 | O9: 51.89371 | P9: 52.30196 | Q9: 52.92555 | R9: 53.420351 | S9: 53.850649 | T9: 55.081922 | U9: 55.757128 | V9: 56.479748 | W9: 57.006353 | X9: 57.569166 | Y9: 57.870235 | Z9: 58.637607 | AA9: 59.329582 | AB9: 59.989461 | AC9: 60.918684 | AD9: 61.620809 | AE9: 61.671533 | AF9: 62.298247 | AG9: 62.755973 | AH9: 62.827507 | AI9: 63.575576 | AJ9: 64.60128 | AK9: 64.850083 | AL9: 65.202506 | AM9: 65.526889 | AN9: 65.852992 | AO9: 66.193579 | AP9: 66.549934 | AQ9: 66.8907 | AR9: 67.240617 | AS9: 67.58063 | AT9: 67.650335 | AU9: 67.733103 | AV9: 68.040502 | AW9: 68.491265 | AX9: 68.879226 | AY9: 69.258133 | AZ9: 69.706904 | BA9: 69.807322 | BB9: 69.363338 | BC9: 69.842317 | BD9: 70.192106 | BE9: 70.535067 | BF9: 70.658012 | BG9: 70.896488 | BH9: 71.112856 | BI9: 71.4313 | BJ9: 71.839893 | BK9: 70.726559 | BL9: 70.404114 | BM9: 71.876096 | BN9: 72.444678 | BO9: 72.721805 | BP9: ARB | BS9: Arab World
A10: United Arab Emirates | B10: ARE | C10: 50.651 | D10: 51.596 | E10: 52.546 | F10: 53.509 | G10: 54.495 | H10: 55.512 | I10: 56.572 | J10: 57.648 | K10: 58.727 | L10: 59.764 | M10: 60.78 | N10: 61.753 | O10: 62.675 | P10: 63.542 | Q10: 64.351 | R10: 65.105 | S10: 65.806 | T10: 66.471 | U10: 67.083 | V10: 67.645 | W10: 68.157 | X10: 68.622 | Y10: 69.056 | Z10: 69.448 | AA10: 69.802 | AB10: 70.123 | AC10: 70.41 | AD10: 70.623 | AE10: 70.808 | AF10: 70.96 | AG10: 71.074 | AH10: 71.144 | AI10: 71.166 | AJ10: 71.159 | AK10: 71.204 | AL10: 71.392 | AM10: 71.82 | AN10: 72.559 | AO10: 73.66 | AP10: 74.982 | AQ10: 76.347 | AR10: 77.621 | AS10: 78.721 | AT10: 79.6 | AU10: 80.272 | AV10: 80.779 | AW10: 81.155 | AX10: 81.438 | AY10: 81.591 | AZ10: 81.679 | BA10: 81.886 | BB10: 81.898 | BC10: 81.913 | BD10: 81.95 | BE10: 81.99 | BF10: 82.076 | BG10: 82.195 | BH10: 82.388 | BI10: 82.449 | BJ10: 82.596 | BK10: 81.936 | BL10: 79.083 | BM10: 80.487 | BN10: 82.909 | BO10: 83.069 | BP10: ARE | BQ10: Middle East & North Africa | BR10: High income | BS10: United Arab Emirates
A11: Argentina | B11: ARG | C11: 64.242 | D11: 64.631 | E11: 64.618 | F11: 64.855 | G11: 64.816 | H11: 65.053 | I11: 65.398 | J11: 65.467 | K11: 65.234 | L11: 65.085 | M11: 65.647 | N11: 65.619 | O11: 65.953 | P11: 66.186 | Q11: 66.405 | R11: 66.965 | S11: 67.03 | T11: 67.595 | U11: 67.999 | V11: 68.434 | W11: 68.576 | X11: 68.858 | Y11: 68.973 | Z11: 69.29 | AA11: 69.353 | AB11: 69.879 | AC11: 70.281 | AD11: 70.699 | AE11: 71.097 | AF11: 71.502 | AG11: 71.615 | AH11: 72.02 | AI11: 72.096 | AJ11: 72.303 | AK11: 72.732 | AL11: 72.864 | AM11: 73.056 | AN11: 73.407 | AO11: 73.412 | AP11: 73.683 | AQ11: 73.91 | AR11: 74.154 | AS11: 74.312 | AT11: 74.307 | AU11: 74.871 | AV11: 75.231 | AW11: 75.279 | AX11: 74.783 | AY11: 75.428 | AZ11: 75.577 | BA11: 75.68 | BB11: 76.1 | BC11: 75.802 | BD11: 75.829 | BE11: 76.268 | BF11: 76.6 | BG11: 76.105 | BH11: 76.543 | BI11: 76.77 | BJ11: 76.847 | BK11: 75.878 | BL11: 73.948 | BM11: 75.806 | BN11: 77.395 | BO11: 77.543 | BP11: ARG | BQ11: Latin America & Caribbean | BR11: Upper middle income | BS11: Argentina
A12: Armenia | B12: ARM | C12: 59.063 | D12: 59.494098 | E12: 59.916683 | F12: 60.328268 | G12: 60.723829 | H12: 61.099341 | I12: 61.453829 | J12: 61.784756 | K12: 62.093634 | L12: 62.379951 | M12: 62.644707 | N12: 62.888902 | O12: 63.114488 | P12: 63.330927 | Q12: 63.546756 | R12: 63.767878 | S12: 64.001488 | T12: 64.253951 | U12: 64.526195 | V12: 64.820829 | W12: 65.138561 | X12: 65.482488 | Y12: 65.850927 | Z12: 66.229244 | AA12: 66.591366 | AB12: 66.915268 | AC12: 67.178 | AD12: 67.359073 | AE12: 52.600122 | AF12: 67.518561 | AG12: 67.549366 | AH12: 67.627049 | AI12: 67.718537 | AJ12: 67.973195 | AK12: 68.271805 | AL12: 68.628488 | AM12: 69.006122 | AN12: 69.393829 | AO12: 69.799341 | AP12: 70.198951 | AQ12: 72.880488 | AR12: 72.97561 | AS12: 72.826829 | AT12: 72.826829 | AU12: 73.026829 | AV12: 73.07561 | AW12: 72.82439 | AX12: 72.873171 | AY12: 73.073171 | AZ12: 73.073171 | BA12: 73.173171 | BB12: 73.817073 | BC12: 74.119512 | BD12: 74.621951 | BE12: 74.873171 | BF12: 74.870732 | BG12: 74.868293 | BH12: 75.217073 | BI12: 75.619512 | BJ12: 76.221951 | BK12: 73.37561 | BL12: 72.278049 | BM12: 74.765854 | BN12: 77.465854 | BO12: 78.319512 | BP12: ARM | BQ12: Europe & Central Asia | BR12: Upper middle income | BS12: Armenia
A13: American Samoa | B13: ASM | C13: 65.053 | D13: 65.648 | E13: 66.008 | F13: 66.161 | G13: 66.135 | H13: 65.996 | I13: 58.284 | J13: 65.807 | K13: 65.847 | L13: 66.05 | M13: 66.364 | N13: 66.77 | O13: 67.186 | P13: 67.604 | Q13: 67.95 | R13: 68.256 | S13: 68.475 | T13: 68.701 | U13: 68.881 | V13: 69.114 | W13: 69.413 | X13: 69.731 | Y13: 69.975 | Z13: 70.163 | AA13: 70.326 | AB13: 70.532 | AC13: 70.704 | AD13: 70.828 | AE13: 70.883 | AF13: 70.929 | AG13: 71.107 | AH13: 71.312 | AI13: 71.511 | AJ13: 71.54 | AK13: 71.569 | AL13: 71.565 | AM13: 71.576 | AN13: 71.606 | AO13: 71.542 | AP13: 71.484 | AQ13: 71.443 | AR13: 71.573 | AS13: 71.755 | AT13: 71.698 | AU13: 72.277 | AV13: 72.382 | AW13: 72.397 | AX13: 72.365 | AY13: 72.43 | AZ13: 70.839 | BA13: 72.587 | BB13: 72.662 | BC13: 72.709 | BD13: 72.769 | BE13: 72.687 | BF13: 72.654 | BG13: 72.64 | BH13: 72.801 | BI13: 72.794 | BJ13: 72.751 | BK13: 72.672 | BL13: 72.708 | BM13: 72.752 | BN13: 72.852 | BO13: 72.992 | BP13: ASM | BQ13: East Asia & Pacific | BR13: High income | BS13: American Samoa
A14: Antigua and Barbuda | B14: ATG | C14: 62.635 | D14: 63.335 | E14: 63.995 | F14: 64.697 | G14: 65.428 | H14: 66.171 | I14: 66.902 | J14: 67.586 | K14: 68.23 | L14: 68.827 | M14: 69.371 | N14: 69.861 | O14: 70.304 | P14: 70.71 | Q14: 71.095 | R14: 71.447 | S14: 71.794 | T14: 72.149 | U14: 72.5 | V14: 72.823 | W14: 73.094 | X14: 73.32 | Y14: 73.525 | Z14: 73.684 | AA14: 73.808 | AB14: 73.873 | AC14: 73.893 | AD14: 73.873 | AE14: 73.811 | AF14: 73.628 | AG14: 73.602 | AH14: 73.472 | AI14: 73.386 | AJ14: 73.39 | AK14: 73.493 | AL14: 73.576 | AM14: 73.839 | AN14: 74.045 | AO14: 74.187 | AP14: 74.456 | AQ14: 74.819 | AR14: 75.108 | AS14: 75.237 | AT14: 75.313 | AU14: 75.329 | AV14: 75.364 | AW14: 75.506 | AX14: 75.72 | AY14: 76.075 | AZ14: 76.386 | BA14: 76.701 | BB14: 77.023 | BC14: 77.1 | BD14: 77.05 | BE14: 76.912 | BF14: 76.892 | BG14: 76.968 | BH14: 77.03 | BI14: 77.132 | BJ14: 77.168 | BK14: 77.161 | BL14: 77.197 | BM14: 77.483 | BN14: 77.598 | BO14: 77.766 | BP14: ATG | BQ14: Latin America & Caribbean | BR14: High income | BS14: Antigua and Barbuda
A15: Australia | B15: AUS | C15: 70.817073 | D15: 70.973171 | E15: 70.942439 | F15: 70.911707 | G15: 70.880976 | H15: 70.850244 | I15: 70.819512 | J15: 70.869268 | K15: 70.919024 | L15: 70.96878 | M15: 71.018537 | N15: 71.068293 | O15: 71.457561 | P15: 71.846829 | Q15: 72.236098 | R15: 72.625366 | S15: 73.014634 | T15: 73.34439 | U15: 73.674146 | V15: 74.003902 | W15: 74.333659 | X15: 74.663415 | Y15: 74.904878 | Z15: 75.146341 | AA15: 75.387805 | AB15: 75.629268 | AC15: 75.870732 | AD15: 76.151707 | AE15: 76.432683 | AF15: 76.713659 | AG15: 76.994634 | AH15: 77.27561 | AI15: 77.378049 | AJ15: 77.878049 | AK15: 77.878049 | AL15: 77.829268 | AM15: 78.078049 | AN15: 78.480488 | AO15: 78.631707 | AP15: 78.931707 | AQ15: 79.234146 | AR15: 79.634146 | AS15: 79.936585 | AT15: 80.239024 | AU15: 80.490244 | AV15: 80.841463 | AW15: 81.041463 | AX15: 81.292683 | AY15: 81.395122 | AZ15: 81.543902 | BA15: 81.695122 | BB15: 81.895122 | BC15: 82.046341 | BD15: 82.14878 | BE15: 82.3 | BF15: 82.4 | BG15: 82.44878 | BH15: 82.5 | BI15: 82.74878 | BJ15: 82.9 | BK15: 83.2 | BL15: 83.3 | BM15: 83.2 | BN15: 83.05122 | BO15: 83.05122 | BP15: AUS | BQ15: East Asia & Pacific | BR15: High income | BS15: Australia
A16: Austria | B16: AUT | C16: 68.58561 | D16: 69.577317 | E16: 69.309512 | F16: 69.443659 | G16: 69.921951 | H16: 69.722195 | I16: 70.045854 | J16: 69.917805 | K16: 70.057561 | L16: 69.833171 | M16: 69.914634 | N16: 70.114634 | O16: 70.463415 | P16: 71.014634 | Q16: 71.012195 | R16: 71.114634 | S16: 71.565854 | T16: 71.914634 | U16: 72.012195 | V16: 72.312195 | W16: 72.463415 | X16: 72.812195 | Y16: 72.960976 | Z16: 73.012195 | AA16: 73.612195 | AB16: 73.814634 | AC16: 74.317073 | AD16: 74.768293 | AE16: 75.217073 | AF16: 75.265854 | AG16: 75.568293 | AH16: 75.617073 | AI16: 75.817073 | AJ16: 76.068293 | AK16: 76.419512 | AL16: 76.668293 | AM16: 76.870732 | AN16: 77.319512 | AO16: 77.670732 | AP16: 77.87561 | AQ16: 78.126829 | AR16: 78.57561 | AS16: 78.678049 | AT16: 78.631707 | AU16: 79.180488 | AV16: 79.331707 | AW16: 79.880488 | AX16: 80.180488 | AY16: 80.431707 | AZ16: 80.331707 | BA16: 80.580488 | BB16: 80.982927 | BC16: 80.936585 | BD16: 81.136585 | BE16: 81.490244 | BF16: 81.190244 | BG16: 81.641463 | BH16: 81.643902 | BI16: 81.692683 | BJ16: 81.895122 | BK16: 81.192683 | BL16: 81.190244 | BM16: 81.295122 | BN16: 81.792683 | BO16: 81.995122 | BP16: AUT | BQ16: Europe & Central Asia | BR16: High income | BS16: Austria
A17: Azerbaijan | B17: AZE | C17: 50.862 | D17: 51.435 | E17: 52.053 | F17: 52.696 | G17: 53.292 | H17: 53.884 | I17: 54.485 | J17: 55.032 | K17: 55.563 | L17: 56.08 | M17: 56.586 | N17: 57.043 | O17: 57.503 | P17: 57.926 | Q17: 58.332 | R17: 58.687 | S17: 59.477 | T17: 59.972 | U17: 60.494 | V17: 60.931 | W17: 61.433 | X17: 61.908 | Y17: 62.23 | Z17: 62.479 | AA17: 62.084 | AB17: 62.674 | AC17: 62.603 | AD17: 62.824 | AE17: 62.672 | AF17: 62.945 | AG17: 62.75 | AH17: 62.544 | AI17: 60.773 | AJ17: 61.426 | AK17: 60.277 | AL17: 61.931 | AM17: 62.66 | AN17: 62.953 | AO17: 63.75 | AP17: 64.733 | AQ17: 65.377 | AR17: 66.043 | AS17: 66.769 | AT17: 67.036 | AU17: 67.488 | AV17: 67.71 | AW17: 68.489 | AX17: 68.659 | AY17: 69.355 | AZ17: 69.874 | BA17: 70.309 | BB17: 70.565 | BC17: 71.08 | BD17: 71.485 | BE17: 71.93 | BF17: 72.349 | BG17: 72.568 | BH17: 72.694 | BI17: 73.016 | BJ17: 73.29 | BK17: 70.312 | BL17: 70.999 | BM17: 74.125 | BN17: 74.429 | BO17: 74.576 | BP17: AZE | BQ17: Europe & Central Asia | BR17: Upper middle income | BS17: Azerbaijan
A18: Burundi | B18: BDI | C18: 43.262 | D18: 43.364 | E18: 43.492 | F18: 43.559 | G18: 43.601 | H18: 41.844 | I18: 43.529 | J18: 43.332 | K18: 43.405 | L18: 43 | M18: 43.225 | N18: 43.172 | O18: 25.777 | P18: 37.409 | Q18: 43.337 | R18: 43.445 | S18: 43.691 | T18: 43.97 | U18: 44.404 | V18: 45.038 | W18: 45.731 | X18: 46.412 | Y18: 47.012 | Z18: 47.433 | AA18: 47.687 | AB18: 47.662 | AC18: 47.402 | AD18: 47.066 | AE18: 42.889 | AF18: 45.745 | AG18: 45.184 | AH18: 44.66 | AI18: 44.469 | AJ18: 37.221 | AK18: 44.515 | AL18: 44.589 | AM18: 44.807 | AN18: 45.721 | AO18: 46.678 | AP18: 47.627 | AQ18: 47.617 | AR18: 48.509 | AS18: 49.924 | AT18: 50.997 | AU18: 52.217 | AV18: 53.053 | AW18: 53.962 | AX18: 54.832 | AY18: 55.581 | AZ18: 56.422 | BA18: 57.088 | BB18: 57.804 | BC18: 58.501 | BD18: 59.179 | BE18: 59.764 | BF18: 60.107 | BG18: 60.789 | BH18: 61.345 | BI18: 61.806 | BJ18: 62.18 | BK18: 62.569 | BL18: 62.101 | BM18: 62.882 | BN18: 63.651 | BO18: 63.818 | BP18: BDI | BQ18: Sub-Saharan Africa | BR18: Low income | BS18: Burundi
A19: Belgium | B19: BEL | C19: 69.701951 | D19: 70.520976 | E19: 70.219512 | F19: 70.051463 | G19: 70.755122 | H19: 70.625366 | I19: 70.706341 | J19: 71.012927 | K19: 70.693171 | L19: 70.764878 | M19: 70.971951 | N19: 71.060488 | O19: 71.405122 | P19: 71.635366 | Q19: 71.985854 | R19: 71.97122 | S19: 72.119756 | T19: 72.773902 | U19: 72.698049 | V19: 73.193659 | W19: 73.207073 | X19: 73.621707 | Y19: 73.888049 | Z19: 73.869024 | AA19: 74.404878 | AB19: 74.520244 | AC19: 74.731707 | AD19: 75.365854 | AE19: 75.565854 | AF19: 75.632683 | AG19: 76.051951 | AH19: 76.192195 | AI19: 76.35122 | AJ19: 76.345366 | AK19: 76.691707 | AL19: 76.840732 | AM19: 77.187317 | AN19: 77.370732 | AO19: 77.473171 | AP19: 77.619512 | AQ19: 77.721951 | AR19: 77.973171 | AS19: 78.07561 | AT19: 78.129268 | AU19: 78.878049 | AV19: 78.980488 | AW19: 79.380488 | AX19: 79.782927 | AY19: 79.680488 | AZ19: 80.034146 | BA19: 80.182927 | BB19: 80.585366 | BC19: 80.385366 | BD19: 80.587805 | BE19: 81.287805 | BF19: 80.992683 | BG19: 81.439024 | BH19: 81.492683 | BI19: 81.595122 | BJ19: 81.995122 | BK19: 80.695122 | BL19: 81.790244 | BM19: 81.74878 | BN19: 82.4 | BO19: 82.3 | BP19: BEL | BQ19: Europe & Central Asia | BR19: High income | BS19: Belgium
A20: Benin | B20: BEN | C20: 38.775 | D20: 39.233 | E20: 39.643 | F20: 40.081 | G20: 40.502 | H20: 40.971 | I20: 41.274 | J20: 41.759 | K20: 42.182 | L20: 42.591 | M20: 43.029 | N20: 43.391 | O20: 43.928 | P20: 44.435 | Q20: 44.876 | R20: 45.405 | S20: 45.952 | T20: 46.504 | U20: 46.941 | V20: 47.362 | W20: 47.747 | X20: 48.122 | Y20: 48.493 | Z20: 48.845 | AA20: 49.399 | AB20: 49.959 | AC20: 50.632 | AD20: 51.258 | AE20: 52.019 | AF20: 52.45 | AG20: 53.02 | AH20: 53.441 | AI20: 54.137 | AJ20: 54.612 | AK20: 54.988 | AL20: 55.366 | AM20: 55.648 | AN20: 55.986 | AO20: 56.154 | AP20: 56.336 | AQ20: 56.594 | AR20: 56.654 | AS20: 56.851 | AT20: 57.092 | AU20: 57.346 | AV20: 57.738 | AW20: 57.966 | AX20: 58.249 | AY20: 58.099 | AZ20: 58.258 | BA20: 58.387 | BB20: 58.462 | BC20: 58.559 | BD20: 58.863 | BE20: 59.008 | BF20: 59.123 | BG20: 59.283 | BH20: 59.528 | BI20: 59.71 | BJ20: 59.888 | BK20: 60.154 | BL20: 59.61 | BM20: 60.475 | BN20: 60.774 | BO20: 60.961 | BP20: BEN | BQ20: Sub-Saharan Africa | BR20: Lower middle income | BS20: Benin
A21: Burkina Faso | B21: BFA | C21: 36.074 | D21: 36.361 | E21: 36.753 | F21: 37.093 | G21: 37.399 | H21: 37.758 | I21: 38.091 | J21: 38.432 | K21: 38.76 | L21: 39.023 | M21: 39.54 | N21: 39.853 | O21: 40.399 | P21: 40.947 | Q21: 41.711 | R21: 42.486 | S21: 43.327 | T21: 44.167 | U21: 44.995 | V21: 45.702 | W21: 46.465 | X21: 46.866 | Y21: 47.633 | Z21: 48.061 | AA21: 48.464 | AB21: 48.748 | AC21: 48.987 | AD21: 49.097 | AE21: 49.215 | AF21: 49.27 | AG21: 49.315 | AH21: 49.33 | AI21: 49.378 | AJ21: 49.412 | AK21: 49.469 | AL21: 49.554 | AM21: 49.693 | AN21: 49.56 | AO21: 50.163 | AP21: 50.463 | AQ21: 50.808 | AR21: 51.188 | AS21: 51.447 | AT21: 51.959 | AU21: 52.6 | AV21: 53.271 | AW21: 53.784 | AX21: 54.377 | AY21: 55.199 | AZ21: 55.791 | BA21: 56.343 | BB21: 57.001 | BC21: 57.457 | BD21: 57.903 | BE21: 58.331 | BF21: 58.778 | BG21: 59.173 | BH21: 59.578 | BI21: 59.972 | BJ21: 60.184 | BK21: 60.454 | BL21: 60.046 | BM21: 60.7 | BN21: 61.092 | BO21: 61.292 | BP21: BFA | BQ21: Sub-Saharan Africa | BR21: Low income | BS21: Burkina Faso
... A37: Canada | B37: CAN | C37: 71.133171 | D37: 71.346098 | E37: 71.367073 | F37: 71.380732 | G37: 71.776341 | H37: 71.872195 | I37: 72.00439 | J37: 72.207805 | K37: 72.353415 | L37: 72.501463 | M37: 72.700488 | N37: 73.029268 | O37: 72.933902 | P37: 73.162683 | Q37: 73.237561 | R37: 73.521707 | S37: 73.856098 | T37: 74.21561 | U37: 74.529756 | V37: 74.866341 | W37: 75.102195 | X37: 75.497805 | Y37: 75.725122 | Z37: 76.060488 | AA37: 76.331951 | AB37: 76.327317 | AC37: 76.463902 | AD37: 76.77878 | AE37: 76.85878 | AF37: 77.124878 | AG37: 77.436585 | AH37: 77.593415 | AI37: 77.838049 | AJ37: 77.704878 | AK37: 77.871707 | AL37: 77.977317 | AM37: 78.220244 | AN37: 78.412439 | AO37: 78.623659 | AP37: 78.839024 | AQ37: 79.166829 | AR37: 79.398049 | AS37: 79.530732 | AT37: 79.715122 | AU37: 79.992195 | AV37: 80.112683 | AW37: 80.543659 | AX37: 80.543659 | AY37: 80.724634 | AZ37: 81.066098 | BA37: 81.322195 | BB37: 81.482683 | BC37: 81.663659 | BD37: 81.744878 | BE37: 81.78439 | BF37: 81.825854 | BG37: 81.94 | BH37: 81.807805 | BI37: 81.803659 | BJ37: 82.158537 | BK37: 81.53 | BL37: 81.451463 | BM37: 81.094878 | BN37: 81.626341 | BO37: 82.108049 | BP37: CAN | BQ37: North America | BR37: High income | BS37: Canada
A38: Central Europe and the Baltics | B38: CEB | C38: 67.943473 | D38: 68.244951 | E38: 67.723736 | F38: 68.701 | G38: 69.195417 | H38: 69.350174 | I38: 69.856985 | J38: 69.355379 | K38: 69.573536 | L38: 69.066603 | M38: 69.345324 | N38: 69.511244 | O38: 69.971171 | P38: 70.109598 | Q38: 70.36857 | R38: 70.180888 | S38: 70.326408 | T38: 70.247694 | U38: 70.149887 | V38: 70.251482 | W38: 69.89341 | X38: 70.37205 | Y38: 70.455473 | Z38: 70.389785 | AA38: 70.349115 | AB38: 70.312883 | AC38: 70.565136 | AD38: 70.611763 | AE38: 70.861708 | AF38: 70.731972 | AG38: 70.656331 | AH38: 70.575221 | AI38: 70.732837 | AJ38: 70.845987 | AK38: 70.869544 | AL38: 71.025421 | AM38: 71.336058 | AN38: 71.517258 | AO38: 71.898238 | AP38: 72.184561 | AQ38: 72.719725 | AR38: 73.096148 | AS38: 73.242415 | AT38: 73.382253 | AU38: 73.730435 | AV38: 73.844995 | AW38: 74.092603 | AX38: 74.250649 | AY38: 74.575953 | AZ38: 74.930364 | BA38: 75.293966 | BB38: 75.888475 | BC38: 76.003394 | BD38: 76.374735 | BE38: 76.68877 | BF38: 76.575512 | BG38: 76.970306 | BH38: 76.929789 | BI38: 76.976438 | BJ38: 77.265914 | BK38: 76.01627 | BL38: 74.723283 | BM38: 76.652299 | BN38: 77.758038 | BO38: 77.918095 | BP38: CEB | BS38: Central Europe and the Baltics
A39: Switzerland | B39: CHE | C39: 71.313415 | D39: 71.644878 | E39: 71.196098 | F39: 71.187561 | G39: 72.077805 | H39: 72.201707 | I39: 72.33561 | J39: 72.636585 | K39: 72.590244 | L39: 72.612683 | M39: 73.020244 | N39: 73.130732 | O39: 73.64439 | P39: 73.940976 | Q39: 74.287073 | R39: 74.66561 | S39: 74.785366 | T39: 75.238049 | U39: 75.187317 | V39: 75.466098 | W39: 75.459268 | X39: 75.693171 | Y39: 76.033902 | Z39: 76.03122 | AA39: 76.608537 | AB39: 76.733659 | AC39: 76.899024 | AD39: 77.197561 | AE39: 77.226585 | AF39: 77.42122 | AG39: 77.242439 | AH39: 77.514634 | AI39: 77.806098 | AJ39: 78.085366 | AK39: 78.35 | AL39: 78.417073 | AM39: 78.896098 | AN39: 79.079512 | AO39: 79.32439 | AP39: 79.580488 | AQ39: 79.680488 | AR39: 80.180488 | AS39: 80.385366 | AT39: 80.536585 | AU39: 81.087805 | AV39: 81.236585 | AW39: 81.490244 | AX39: 81.741463 | AY39: 81.992683 | AZ39: 82.043902 | BA39: 82.246341 | BB39: 82.695122 | BC39: 82.697561 | BD39: 82.797561 | BE39: 83.197561 | BF39: 82.897561 | BG39: 83.602439 | BH39: 83.55122 | BI39: 83.753659 | BJ39: 83.904878 | BK39: 83 | BL39: 83.75122 | BM39: 83.604878 | BN39: 84.156098 | BO39: 84.407317 | BP39: CHE | BQ39: Europe & Central Asia | BR39: High income | BS39: Switzerland
A40: Channel Islands | B40: CHI | C40: 72.5 | D40: 71.6 | E40: 72 | F40: 72.2 | G40: 72 | H40: 71.6 | I40: 72.3 | J40: 72.2 | K40: 71.7 | L40: 71.7 | M40: 71.8 | N40: 72 | O40: 72 | P40: 72.7 | Q40: 72.5 | R40: 72.6 | S40: 72.7 | T40: 72.9 | U40: 73.1 | V40: 73.2 | W40: 73.9 | X40: 73.8 | Y40: 73.1 | Z40: 74.9 | AA40: 75.2 | AB40: 75.3 | AC40: 75.4 | AD40: 75.7 | AE40: 76 | AF40: 76.5 | AG40: 76.3 | AH40: 76.5 | AI40: 77.1 | AJ40: 76.8 | AK40: 77 | AL40: 77.7 | AM40: 77.8 | AN40: 78.2 | AO40: 78.5 | AP40: 79.1 | AQ40: 78.8 | AR40: 79 | AS40: 79.1 | AT40: 79.4 | AU40: 79.8 | AV40: 80.1 | AW40: 80.4 | AX40: 80.6 | AY40: 80.8 | AZ40: 81 | BA40: 81.2 | BB40: 81.4 | BC40: 81.3 | BD40: 81.5 | BE40: 81.6 | BF40: 81.4 | BG40: 81.2 | BH40: 81 | BI40: 81.1 | BJ40: 81.2 | BK40: 80.9 | BL40: 80.3 | BM40: 81 | BN40: 81.1 | BO40: 81.2 | BP40: CHI | BQ40: Europe & Central Asia | BR40: High income | BS40: Channel Islands
A41: Chile | B41: CHL | C41: 57.216 | D41: 57.309 | E41: 57.811 | F41: 58.349 | G41: 58.812 | H41: 59.473 | I41: 60.373 | J41: 61.054 | K41: 61.68 | L41: 62.341 | M41: 62.634 | N41: 63.072 | O41: 63.717 | P41: 64.42 | Q41: 65.085 | R41: 66.037 | S41: 66.819 | T41: 67.529 | U41: 68.042 | V41: 68.858 | W41: 69.475 | X41: 69.822 | Y41: 70.291 | Z41: 70.83 | AA41: 71.215 | AB41: 71.615 | AC41: 72.061 | AD41: 72.466 | AE41: 72.788 | AF41: 73.188 | AG41: 73.675 | AH41: 74.082 | AI41: 74.367 | AJ41: 74.679 | AK41: 74.973 | AL41: 75.298 | AM41: 75.555 | AN41: 75.826 | AO41: 76.324 | AP41: 76.738 | AQ41: 77.128 | AR41: 77.58 | AS41: 77.84 | AT41: 77.884 | AU41: 78.276 | AV41: 78.459 | AW41: 78.533 | AX41: 78.652 | AY41: 78.752 | AZ41: 78.89 | BA41: 79.095 | BB41: 79.236 | BC41: 79.221 | BD41: 79.551 | BE41: 79.714 | BF41: 80.008 | BG41: 80.295 | BH41: 80.61 | BI41: 80.559 | BJ41: 80.324 | BK41: 79.349 | BL41: 78.876 | BM41: 79.176 | BN41: 81.167 | BO41: 81.359 | BP41: CHL | BQ41: Latin America & Caribbean | BR41: High income | BS41: Chile
A42: China | B42: CHN | C42: 33.419 | D42: 40.158 | E42: 50.959 | F42: 51.67 | G42: 52.343 | H42: 53.001 | I42: 53.662 | J42: 54.401 | K42: 55.191 | L42: 55.988 | M42: 56.824 | N42: 57.731 | O42: 58.579 | P42: 59.496 | Q42: 60.241 | R42: 60.952 | S42: 61.225 | T42: 62.458 | U42: 63.102 | V42: 63.704 | W42: 64.243 | X42: 64.778 | Y42: 65.249 | Z42: 65.728 | AA42: 66.148 | AB42: 66.532 | AC42: 66.887 | AD42: 67.263 | AE42: 67.607 | AF42: 67.93 | AG42: 68.155 | AH42: 68.61 | AI42: 69.059 | AJ42: 69.492 | AK42: 69.835 | AL42: 70.363 | AM42: 70.823 | AN42: 71.227 | AO42: 71.601 | AP42: 71.952 | AQ42: 72.288 | AR42: 72.675 | AS42: 73.034 | AT42: 73.385 | AU42: 73.727 | AV42: 74.085 | AW42: 74.404 | AX42: 74.789 | AY42: 74.833 | AZ42: 75.317 | BA42: 75.668 | BB42: 75.889 | BC42: 76.2 | BD42: 76.452 | BE42: 76.714 | BF42: 76.975 | BG42: 77.214 | BH42: 77.235 | BI42: 77.709 | BJ42: 77.94 | BK42: 78.019 | BL42: 78.117 | BM42: 78.202 | BN42: 77.953 | BO42: 78.017 | BP42: CHN | BQ42: East Asia & Pacific | BR42: Upper middle income | BS42: China
A43: Cote d'Ivoire | B43: CIV | C43: 37.244 | D43: 37.923 | E43: 38.62 | F43: 39.315 | G43: 39.966 | H43: 40.643 | I43: 41.297 | J43: 41.959 | K43: 42.648 | L43: 43.345 | M43: 44.045 | N43: 44.783 | O43: 45.575 | P43: 46.372 | Q43: 47.207 | R43: 48.03 | S43: 48.863 | T43: 49.624 | U43: 50.361 | V43: 50.983 | W43: 51.437 | X43: 51.791 | Y43: 52.09 | Z43: 52.352 | AA43: 52.648 | AB43: 52.861 | AC43: 53.009 | AD43: 53.118 | AE43: 53.062 | AF43: 52.955 | AG43: 52.796 | AH43: 52.621 | AI43: 52.429 | AJ43: 52.247 | AK43: 52.005 | AL43: 51.713 | AM43: 51.596 | AN43: 51.498 | AO43: 51.22 | AP43: 51.273 | AQ43: 51.393 | AR43: 51.428 | AS43: 51.544 | AT43: 51.443 | AU43: 51.939 | AV43: 52.432 | AW43: 52.885 | AX43: 53.452 | AY43: 54.179 | AZ43: 54.744 | BA43: 55.282 | BB43: 55.972 | BC43: 56.57 | BD43: 57.057 | BE43: 57.772 | BF43: 58.281 | BG43: 58.814 | BH43: 59.315 | BI43: 59.795 | BJ43: 60.274 | BK43: 60.14 | BL43: 60.29 | BM43: 61.562 | BN43: 61.944 | BO43: 62.11 | BP43: CIV | BQ43: Sub-Saharan Africa | BR43: Lower middle income | BS43: Côte d'Ivoire
A44: Cameroon | B44: CMR | C44: 34.667 | D44: 35.186 | E44: 42.599 | F44: 43.074 | G44: 43.596 | H44: 44.175 | I44: 44.839 | J44: 45.602 | K44: 46.389 | L44: 47.191 | M44: 47.954 | N44: 48.577 | O44: 49.12 | P44: 49.517 | Q44: 49.734 | R44: 49.891 | S44: 50.017 | T44: 50.13 | U44: 50.319 | V44: 50.535 | W44: 50.852 | X44: 51.227 | Y44: 51.801 | Z44: 52.447 | AA44: 52.886 | AB44: 53.465 | AC44: 53.572 | AD44: 54.188 | AE44: 54.359 | AF44: 54.389 | AG44: 54.348 | AH44: 54.168 | AI44: 54.053 | AJ44: 53.872 | AK44: 53.537 | AL44: 53.347 | AM44: 53.2 | AN44: 53.105 | AO44: 53.043 | AP44: 53.166 | AQ44: 53.338 | AR44: 53.598 | AS44: 53.922 | AT44: 54.253 | AU44: 54.578 | AV44: 54.904 | AW44: 55.301 | AX44: 55.71 | AY44: 56.116 | AZ44: 56.486 | BA44: 56.965 | BB44: 57.482 | BC44: 58.17 | BD44: 58.73 | BE44: 59.13 | BF44: 59.687 | BG44: 60.293 | BH44: 60.817 | BI44: 61.189 | BJ44: 61.695 | BK44: 61.674 | BL44: 61.146 | BM44: 62.443 | BN44: 63.7 | BO44: 63.968 | BP44: CMR | BQ44: Sub-Saharan Africa | BR44: Lower middle income | BS44: Cameroon
A45: Congo, Dem. Rep. | B45: COD | C45: 40.752 | D45: 40.161 | E45: 40.382 | F45: 40.604 | G45: 40.099 | H45: 40.767 | I45: 42.169 | J45: 42.339 | K45: 42.667 | L45: 42.959 | M45: 43.3 | N45: 43.578 | O45: 43.869 | P45: 44.09 | Q45: 44.311 | R45: 44.53 | S45: 44.695 | T45: 44.866 | U45: 44.628 | V45: 45.278 | W45: 45.543 | X45: 45.726 | Y45: 45.946 | Z45: 46.207 | AA45: 46.514 | AB45: 46.663 | AC45: 47.016 | AD45: 47.362 | AE45: 47.755 | AF45: 48.149 | AG45: 48.538 | AH45: 48.944 | AI45: 49.323 | AJ45: 49.621 | AK45: 49.88 | AL45: 50.381 | AM45: 49.376 | AN45: 50.461 | AO45: 49.664 | AP45: 50.089 | AQ45: 51.887 | AR45: 52.205 | AS45: 52.371 | AT45: 52.952 | AU45: 53.534 | AV45: 54.001 | AW45: 54.498 | AX45: 54.954 | AY45: 55.388 | AZ45: 55.798 | BA45: 56.411 | BB45: 56.911 | BC45: 57.35 | BD45: 57.795 | BE45: 58.236 | BF45: 58.658 | BG45: 59.081 | BH45: 59.495 | BI45: 59.926 | BJ45: 60.242 | BK45: 60.428 | BL45: 60.044 | BM45: 60.979 | BN45: 61.895 | BO45: 62.074 | BP45: COD | BQ45: Sub-Saharan Africa | BR45: Low income | BS45: Congo, Dem. Rep.
A46: Congo, Rep. | B46: COG | C46: 47.595 | D46: 48.351 | E46: 49.038 | F46: 49.729 | G46: 50.363 | H46: 50.996 | I46: 51.557 | J46: 51.91 | K46: 52.62 | L46: 53.114 | M46: 53.555 | N46: 53.983 | O46: 54.361 | P46: 54.744 | Q46: 55.053 | R46: 55.402 | S46: 55.699 | T46: 56.027 | U46: 56.248 | V46: 56.524 | W46: 56.803 | X46: 57.065 | Y46: 57.236 | Z46: 57.428 | AA46: 57.54 | AB46: 57.608 | AC46: 57.633 | AD46: 57.59 | AE46: 57.493 | AF46: 57.292 | AG46: 57.07 | AH46: 56.764 | AI46: 56.483 | AJ46: 56.041 | AK46: 55.641 | AL46: 55.474 | AM46: 55.24 | AN46: 48.575 | AO46: 52.551 | AP46: 54.427 | AQ46: 55.371 | AR46: 55.885 | AS46: 56.414 | AT46: 57.131 | AU46: 57.957 | AV46: 58.73 | AW46: 59.474 | AX46: 60.05 | AY46: 60.79 | AZ46: 61.215 | BA46: 61.731 | BB46: 62.286 | BC46: 62.662 | BD46: 62.969 | BE46: 63.349 | BF46: 63.662 | BG46: 63.911 | BH46: 64.203 | BI46: 64.472 | BJ46: 63.152 | BK46: 64.391 | BL46: 64.192 | BM46: 65 | BN46: 65.772 | BO46: 66.001 | BP46: COG | BQ46: Sub-Saharan Africa | BR46: Lower middle income | BS46: Congo, Rep.
A47: Colombia | B47: COL | C47: 56.609 | D47: 57.203 | E47: 57.737 | F47: 58.296 | G47: 58.77 | H47: 59.247 | I47: 59.713 | J47: 60.15 | K47: 60.572 | L47: 61.031 | M47: 61.465 | N47: 62.005 | O47: 62.53 | P47: 62.991 | Q47: 63.497 | R47: 64.012 | S47: 64.642 | T47: 65.237 | U47: 65.827 | V47: 66.162 | W47: 66.693 | X47: 67.189 | Y47: 67.861 | Z47: 68.121 | AA47: 68.308 | AB47: 65.359 | AC47: 68.303 | AD47: 68.166 | AE47: 68.301 | AF47: 68.616 | AG47: 68.701 | AH47: 68.772 | AI47: 68.764 | AJ47: 69.083 | AK47: 69.422 | AL47: 69.81 | AM47: 70.209 | AN47: 70.632 | AO47: 70.924 | AP47: 70.913 | AQ47: 70.905 | AR47: 71.185 | AS47: 71.537 | AT47: 72.309 | AU47: 72.76 | AV47: 73.156 | AW47: 73.497 | AX47: 73.751 | AY47: 74.206 | AZ47: 74.531 | BA47: 74.876 | BB47: 75.18 | BC47: 75.611 | BD47: 75.834 | BE47: 75.95 | BF47: 76.067 | BG47: 76.228 | BH47: 76.418 | BI47: 76.579 | BJ47: 76.793 | BK47: 74.757 | BL47: 72.698 | BM47: 76.508 | BN47: 77.725 | BO47: 77.913 | BP47: COL | BQ47: Latin America & Caribbean | BR47: Upper middle income | BS47: Colombia
A48: Comoros | B48: COM | C48: 40.777 | D48: 41.157 | E48: 41.534 | F48: 41.909 | G48: 42.328 | H48: 42.676 | I48: 43.153 | J48: 43.593 | K48: 44.101 | L48: 44.643 | M48: 45.226 | N48: 45.849 | O48: 46.463 | P48: 47.045 | Q48: 47.609 | R48: 46.866 | S48: 48.645 | T48: 49.17 | U48: 49.702 | V48: 50.126 | W48: 50.681 | X48: 51.211 | Y48: 51.75 | Z48: 52.121 | AA48: 52.784 | AB48: 53.263 | AC48: 53.756 | AD48: 54.134 | AE48: 54.678 | AF48: 54.983 | AG48: 55.62 | AH48: 56.104 | AI48: 56.576 | AJ48: 57.026 | AK48: 57.458 | AL48: 57.83 | AM48: 58.151 | AN48: 58.228 | AO48: 58.301 | AP48: 58.853 | AQ48: 58.941 | AR48: 59.587 | AS48: 59.723 | AT48: 60.24 | AU48: 60.557 | AV48: 60.883 | AW48: 61.229 | AX48: 61.475 | AY48: 61.955 | AZ48: 62.302 | BA48: 62.747 | BB48: 63.105 | BC48: 63.463 | BD48: 63.839 | BE48: 64.143 | BF48: 64.473 | BG48: 64.792 | BH48: 65.127 | BI48: 65.401 | BJ48: 65.662 | BK48: 65.756 | BL48: 65.201 | BM48: 66.481 | BN48: 66.777 | BO48: 67.023 | BP48: COM | BQ48: Sub-Saharan Africa | BR48: Lower middle income | BS48: Comoros
A49: Cabo Verde | B49: CPV | C49: 48.713 | D49: 49.419 | E49: 50.239 | F49: 51.145 | G49: 52.089 | H49: 53.04 | I49: 53.922 | J49: 54.716 | K49: 55.426 | L49: 56.038 | M49: 56.559 | N49: 57.027 | O49: 57.486 | P49: 57.979 | Q49: 58.432 | R49: 58.976 | S49: 59.396 | T49: 59.986 | U49: 60.381 | V49: 60.726 | W49: 61.031 | X49: 61.299 | Y49: 61.519 | Z49: 61.767 | AA49: 61.829 | AB49: 62.281 | AC49: 62.584 | AD49: 62.91 | AE49: 63.242 | AF49: 63.566 | AG49: 63.869 | AH49: 64.066 | AI49: 64.253 | AJ49: 64.458 | AK49: 64.648 | AL49: 63.691 | AM49: 65.521 | AN49: 66.082 | AO49: 66.714 | AP49: 67.409 | AQ49: 68.117 | AR49: 68.707 | AS49: 69.447 | AT49: 70.006 | AU49: 70.499 | AV49: 70.936 | AW49: 71.341 | AX49: 71.487 | AY49: 71.888 | AZ49: 72.142 | BA49: 72.507 | BB49: 72.913 | BC49: 73.315 | BD49: 73.481 | BE49: 73.788 | BF49: 74.096 | BG49: 74.35 | BH49: 74.71 | BI49: 74.84 | BJ49: 75.449 | BK49: 73.818 | BL49: 74.424 | BM49: 75.907 | BN49: 76.059 | BO49: 76.224 | BP49: CPV | BQ49: Sub-Saharan Africa | BR49: Upper middle income | BS49: Cabo Verde
A50: Costa Rica | B50: CRI | C50: 63.463 | D50: 63.86 | E50: 64.232 | F50: 64.326 | G50: 64.493 | H50: 64.76 | I50: 65.096 | J50: 65.552 | K50: 65.78 | L50: 66.363 | M50: 66.787 | N50: 67.413 | O50: 68.014 | P50: 68.731 | Q50: 69.446 | R50: 70.253 | S50: 70.946 | T50: 71.519 | U50: 72.029 | V50: 72.537 | W50: 73.034 | X50: 73.441 | Y50: 73.865 | Z50: 74.245 | AA50: 74.581 | AB50: 74.765 | AC50: 74.949 | AD50: 75.224 | AE50: 75.546 | AF50: 75.85 | AG50: 76.094 | AH50: 76.237 | AI50: 76.385 | AJ50: 76.315 | AK50: 76.329 | AL50: 76.44 | AM50: 76.428 | AN50: 76.603 | AO50: 76.869 | AP50: 77.058 | AQ50: 77.317 | AR50: 77.609 | AS50: 77.939 | AT50: 78.214 | AU50: 78.512 | AV50: 78.877 | AW50: 79.049 | AX50: 79.098 | AY50: 79.18 | AZ50: 79.372 | BA50: 79.354 | BB50: 79.624 | BC50: 79.925 | BD50: 80.189 | BE50: 80.231 | BF50: 80.407 | BG50: 79.988 | BH50: 79.994 | BI50: 80.09 | BJ50: 80.296 | BK50: 79.725 | BL50: 78.05 | BM50: 79.316 | BN50: 80.799 | BO50: 80.996 | BP50: CRI | BQ50: Latin America & Caribbean | BR50: High income | BS50: Costa Rica
A51: Caribbean small states | B51: CSS | C51: 60.296076 | D51: 60.671113 | E51: 61.366755 | F51: 61.717282 | G51: 62.116938 | H51: 62.427899 | I51: 62.688492 | J51: 62.919213 | K51: 63.147976 | L51: 63.33756 | M51: 63.491125 | N51: 63.642161 | O51: 63.85759 | P51: 64.052426 | Q51: 64.263256 | R51: 64.483005 | S51: 64.756251 | T51: 64.972608 | U51: 65.124541 | V51: 65.347242 | W51: 65.501582 | X51: 65.663476 | Y51: 65.778323 | Z51: 65.84727 | AA51: 66.13987 | AB51: 66.30206 | AC51: 66.411303 | AD51: 66.570945 | AE51: 66.74044 | AF51: 66.9248 | AG51: 67.045151 | AH51: 67.219377 | AI51: 67.353289 | AJ51: 67.475565 | AK51: 67.521661 | AL51: 67.555572 | AM51: 67.626402 | AN51: 67.736543 | AO51: 67.984923 | AP51: 68.209564 | AQ51: 68.397676 | AR51: 68.661972 | AS51: 68.899714 | AT51: 69.087649 | AU51: 69.36097 | AV51: 69.632051 | AW51: 69.934423 | AX51: 70.293733 | AY51: 70.549997 | AZ51: 70.797738 | BA51: 71.011437 | BB51: 71.266093 | BC51: 71.401914 | BD51: 71.569251 | BE51: 71.773941 | BF51: 71.864102 | BG51: 72.051636 | BH51: 72.173104 | BI51: 72.221085 | BJ51: 72.12926 | BK51: 71.939436 | BL51: 69.922811 | BM51: 72.832292 | BN51: 73.171645 | BO51: 73.312667 | BP51: CSS | BS51: Caribbean small states
A52: Cuba | B52: CUB | C52: 63.316 | D52: 63.743 | E52: 64.374 | F52: 64.347 | G52: 65.264 | H52: 65.636 | I52: 66.074 | J52: 66.514 | K52: 66.944 | L52: 67.358 | M52: 67.935 | N52: 68.432 | O52: 68.949 | P52: 69.347 | Q52: 69.867 | R52: 70.375 | S52: 70.878 | T52: 71.411 | U52: 71.89 | V52: 72.272 | W52: 72.603 | X52: 72.996 | Y52: 73.439 | Z52: 73.564 | AA52: 73.552 | AB52: 73.464 | AC52: 73.558 | AD52: 73.596 | AE52: 73.724 | AF52: 73.69 | AG52: 73.823 | AH52: 73.757 | AI52: 73.846 | AJ52: 73.874 | AK52: 74.092 | AL52: 74.346 | AM52: 74.69 | AN52: 75.064 | AO52: 75.412 | AP52: 75.719 | AQ52: 75.922 | AR52: 76.429 | AS52: 76.766 | AT52: 77.405 | AU52: 77.326 | AV52: 77.54 | AW52: 77.406 | AX52: 77.55 | AY52: 77.589 | AZ52: 77.584 | BA52: 77.876 | BB52: 78.051 | BC52: 78.162 | BD52: 78.028 | BE52: 77.825 | BF52: 77.745 | BG52: 77.571 | BH52: 77.3 | BI52: 77.426 | BJ52: 77.413 | BK52: 77.407 | BL52: 73.201 | BM52: 77.629 | BN52: 78.085 | BO52: 78.264 | BP52: CUB | BQ52: Latin America & Caribbean | BR52: Upper middle income | BS52: Cuba
A53: Curacao | B53: CUW | C53: 65.406 | D53: 65.745 | E53: 66.027 | F53: 66.312 | G53: 66.59 | H53: 66.862 | I53: 67.136 | J53: 67.405 | K53: 67.67 | L53: 67.929 | M53: 68.23 | N53: 68.505 | O53: 68.811 | P53: 69.092 | Q53: 69.394 | R53: 69.672 | S53: 69.951 | T53: 70.202 | U53: 70.445 | V53: 70.716 | W53: 70.951 | X53: 71.175 | Y53: 71.377 | Z53: 71.534 | AA53: 71.715 | AB53: 71.867 | AC53: 71.996 | AD53: 72.139 | AE53: 72.23 | AF53: 72.151 | AG53: 72.439 | AH53: 72.536 | AI53: 72.65 | AJ53: 72.703 | AK53: 72.791 | AL53: 72.831 | AM53: 72.945 | AN53: 73.035 | AO53: 73.084 | AP53: 73.174 | AQ53: 73.283 | AR53: 73.36 | AS53: 73.472 | AT53: 73.603 | AU53: 73.735 | AV53: 73.873 | AW53: 73.978 | AX53: 74.137 | AY53: 74.314 | AZ53: 74.485 | BA53: 75.117 | BB53: 75.576 | BC53: 75.96 | BD53: 76.239 | BE53: 76.384 | BF53: 76.482 | BG53: 76.322 | BH53: 76.423 | BI53: 76.493 | BJ53: 76.492 | BK53: 76.501 | BL53: 75.686 | BM53: 76.729 | BN53: 76.8 | BO53: 76.989 | BP53: CUW | BQ53: Latin America & Caribbean | BR53: High income | BS53: Curaçao
A54: Cayman Islands | B54: CYM | C54: 58.782 | D54: 59.426 | E54: 60.09 | F54: 60.78 | G54: 61.436 | H54: 62.186 | I54: 62.841 | J54: 63.205 | K54: 63.597 | L54: 63.965 | M54: 64.383 | N54: 64.827 | O54: 65.365 | P54: 65.889 | Q54: 66.489 | R54: 67.044 | S54: 67.549 | T54: 68.08 | U54: 68.533 | V54: 69.02 | W54: 69.487 | X54: 69.951 | Y54: 70.407 | Z54: 70.839 | AA54: 71.187 | AB54: 71.558 | AC54: 71.869 | AD54: 72.13 | AE54: 72.351 | AF54: 72.545 | AG54: 72.744 | AH54: 72.911 | AI54: 73.088 | AJ54: 73.25 | AK54: 73.42 | AL54: 73.597 | AM54: 73.74 | AN54: 73.904 | AO54: 74.08 | AP54: 74.232 | AQ54: 74.378 | AR54: 74.529 | AS54: 74.609 | AT54: 74.639 | AU54: 74.596 | AV54: 74.863 | AW54: 75 | AX54: 75.152 | AY54: 75.386 | AZ54: 75.671 | BA54: 76.069 | BB54: 76.562 | BC54: 77.121 | BD54: 77.652 | BE54: 77.865 | BF54: 78.119 | BG54: 78.367 | BH54: 78.615 | BI54: 78.835 | BJ54: 79.052 | BK54: 79.23 | BL54: 79.3 | BM54: 79.984 | BN54: 80.358 | BO54: 80.54 | BP54: CYM | BQ54: Latin America & Caribbean | BR54: High income | BS54: Cayman Islands
A55: Cyprus | B55: CYP | C55: 63.32 | D55: 64.076 | E55: 64.72 | F55: 61.779 | G55: 62.24 | H55: 66.124 | I55: 66.489 | J55: 66.906 | K55: 67.251 | L55: 67.599 | M55: 68.05 | N55: 68.351 | O55: 68.629 | P55: 69.005 | Q55: 54.551 | R55: 70.336 | S55: 70.805 | T55: 71.258 | U55: 71.741 | V55: 72.179 | W55: 72.844 | X55: 73.053 | Y55: 73.518 | Z55: 73.708 | AA55: 74 | AB55: 74.64 | AC55: 74.93 | AD55: 75.264 | AE55: 75.39 | AF55: 75.841 | AG55: 76.044 | AH55: 76.246 | AI55: 76.291 | AJ55: 76.294 | AK55: 76.383 | AL55: 76.583 | AM55: 76.88 | AN55: 77.119 | AO55: 77.164 | AP55: 77.572 | AQ55: 77.9 | AR55: 78.185 | AS55: 78.758 | AT55: 78.908 | AU55: 79.007 | AV55: 79.198 | AW55: 79.456 | AX55: 79.798 | AY55: 79.906 | AZ55: 80.375 | BA55: 80.632 | BB55: 80.855 | BC55: 81.128 | BD55: 81.317 | BE55: 81.337 | BF55: 81.464 | BG55: 81.534 | BH55: 81.543 | BI55: 81.556 | BJ55: 81.454 | BK55: 81.23 | BL55: 80.573 | BM55: 80.434 | BN55: 81.648 | BO55: 81.821 | BP55: CYP | BQ55: Europe & Central Asia | BR55: High income | BS55: Cyprus
...

Sheet Avg
A3: Row Labels | B3: Average of 2024 | C3: Average of 2020
B4: 72.106629 | C4: 70.508778
A5: East Asia & Pacific | B5: 74.114659 | C5: 73.433013
A6: Europe & Central Asia | B6: 79.26316 | C6: 77.751736
A7: Latin America & Caribbean | B7: 75.519823 | C7: 73.800964
A8: Middle East & North Africa | B8: 75.925572 | C8: 74.081405
A9: North America | B9: 81.162764 | C9: 79.988829
A10: South Asia | B10: 75.003333 | C10: 73.096167
A11: Sub-Saharan Africa | B11: 64.778003 | C11: 62.97966
A12: Grand Total | B12: 73.659383 | C12: 72.130009

Sheet Fact_WorldBank (2)
A1: Country Name | B1: Country Code | C1: Year | D1: Value
A2: Aruba | B2: ABW | C2: 1960 | D2: 64.049
A3: Aruba | B3: ABW | C3: 1961 | D3: 64.215
A4: Aruba | B4: ABW | C4: 1962 | D4: 64.602
A5: Aruba | B5: ABW | C5: 1963 | D5: 64.944
A6: Aruba | B6: ABW | C6: 1964 | D6: 65.303
A7: Aruba | B7: ABW | C7: 1965 | D7: 65.615
A8: Aruba | B8: ABW | C8: 1966 | D8: 66.126
A9: Aruba | B9: ABW | C9: 1967 | D9: 66.385
A10: Aruba | B10: ABW | C10: 1968 | D10: 66.744
A11: Aruba | B11: ABW | C11: 1969 | D11: 67.098
A12: Aruba | B12: ABW | C12: 1970 | D12: 67.44
A13: Aruba | B13: ABW | C13: 1971 | D13: 67.783
... A17192: Zimbabwe | B17192: ZWE | C17192: 2024 | D17192: 63.064

Sheet Dim_Year
A1: Year
A2: 1960
A3: 1961
A4: 1962
A5: 1963
A6: 1964
A7: 1965
A8: 1966
A9: 1967
A10: 1968
A11: 1969
A12: 1970
A13: 1971
... A17192: 2024

Sheet LifeExpctClean
A1: Country Name | B1: Country Code | C1: 1960 | D1: 1961 | E1: 1962 | F1: 1963 | G1: 1964 | H1: 1965 | I1: 1966 | J1: 1967 | K1: 1968 | L1: 1969 | M1: 1970 | N1: 1971 | O1: 1972 | P1: 1973 | Q1: 1974 | R1: 1975 | S1: 1976 | T1: 1977 | U1: 1978 | V1: 1979 | W1: 1980 | X1: 1981 | Y1: 1982 | Z1: 1983 | AA1: 1984 | AB1: 1985 | AC1: 1986 | AD1: 1987 | AE1: 1988 | AF1: 1989 | AG1: 1990 | AH1: 1991 | AI1: 1992 | AJ1: 1993 | AK1: 1994 | AL1: 1995 | AM1: 1996 | AN1: 1997 | AO1: 1998 | AP1: 1999 | AQ1: 2000 | AR1: 2001 | AS1: 2002 | AT1: 2003 | AU1: 2004 | AV1: 2005 | AW1: 2006 | AX1: 2007 | AY1: 2008 | AZ1: 2009 | BA1: 2010 | BB1: 2011 | BC1: 2012 | BD1: 2013 | BE1: 2014 | BF1: 2015 | BG1: 2016 | BH1: 2017 | BI1: 2018 | BJ1: 2019 | BK1: 2020 | BL1: 2021 | BM1: 2022 | BN1: 2023 | BO1: 2024 | BP1: Region | BQ1: Income Level
A2: Aruba | B2: ABW | C2: 64.049 | D2: 64.215 | E2: 64.602 | F2: 64.944 | G2: 65.303 | H2: 65.615 | I2: 66.126 | J2: 66.385 | K2: 66.744 | L2: 67.098 | M2: 67.44 | N2: 67.783 | O2: 68.335 | P2: 68.862 | Q2: 69.278 | R2: 69.564 | S2: 69.808 | T2: 70.054 | U2: 70.271 | V2: 70.507 | W2: 70.771 | X2: 71.344 | Y2: 71.485 | Z2: 71.606 | AA2: 71.711 | AB2: 71.792 | AC2: 71.831 | AD2: 72.448 | AE2: 72.519 | AF2: 72.531 | AG2: 72.546 | AH2: 72.592 | AI2: 72.717 | AJ2: 72.777 | AK2: 72.796 | AL2: 72.832 | AM2: 72.856 | AN2: 72.904 | AO2: 72.94 | AP2: 72.857 | AQ2: 72.939 | AR2: 73.044 | AS2: 73.135 | AT2: 73.236 | AU2: 73.223 | AV2: 73.415 | AW2: 73.498 | AX2: 73.642 | AY2: 73.783 | AZ2: 73.974 | BA2: 74.297 | BB2: 74.578 | BC2: 74.841 | BD2: 75.072 | BE2: 75.261 | BF2: 75.405 | BG2: 75.54 | BH2: 75.62 | BI2: 75.88 | BJ2: 76.019 | BK2: 75.406 | BL2: 73.655 | BM2: 76.226 | BN2: 76.353 | BO2: 76.5
A3: Africa Eastern and Southern | B3: AFE | C3: 44.169658 | D3: 44.468838 | E3: 44.87789 | F3: 45.160583 | G3: 45.535695 | H3: 45.770723 | I3: 45.765725 | J3: 46.440745 | K3: 46.738632 | L3: 46.977476 | M3: 47.248006 | N3: 47.464016 | O3: 47.166792 | P3: 47.746608 | Q3: 47.744328 | R3: 47.968548 | S3: 48.568138 | T3: 48.860725 | U3: 48.983917 | V3: 49.416988 | W3: 49.816713 | X3: 50.020493 | Y3: 50.290829 | Z3: 48.904096 | AA3: 48.997959 | AB3: 49.392902 | AC3: 50.009761 | AD3: 51.068943 | AE3: 50.876607 | AF3: 51.265874 | AG3: 51.096326 | AH3: 50.873244 | AI3: 50.715946 | AJ3: 51.073762 | AK3: 50.966589 | AL3: 51.482057 | AM3: 51.35319 | AN3: 51.570887 | AO3: 51.317955 | AP3: 51.807077 | AQ3: 52.557342 | AR3: 52.875536 | AS3: 53.206744 | AT3: 53.678305 | AU3: 54.192928 | AV3: 54.807681 | AW3: 55.693515 | AX3: 56.484353 | AY3: 57.240106 | AZ3: 58.095527 | BA3: 58.827279 | BB3: 59.200004 | BC3: 60.249512 | BD3: 60.89574 | BE3: 61.251436 | BF3: 61.713031 | BG3: 62.167981 | BH3: 62.591275 | BI3: 63.330691 | BJ3: 63.857261 | BK3: 63.766484 | BL3: 62.979999 | BM3: 64.487152 | BN3: 65.146228 | BO3: 65.34993
A4: Afghanistan | B4: AFG | C4: 32.799 | D4: 33.291 | E4: 33.757 | F4: 34.201 | G4: 34.673 | H4: 35.124 | I4: 35.583 | J4: 36.042 | K4: 36.51 | L4: 36.979 | M4: 37.46 | N4: 37.932 | O4: 38.423 | P4: 38.951 | Q4: 39.469 | R4: 39.994 | S4: 40.518 | T4: 41.082 | U4: 40.086 | V4: 38.844 | W4: 39.258 | X4: 39.406 | Y4: 36.058 | Z4: 36.517 | AA4: 31.473 | AB4: 32.132 | AC4: 38.4 | AD4: 38.831 | AE4: 43.238 | AF4: 44.496 | AG4: 45.118 | AH4: 45.521 | AI4: 46.569 | AJ4: 51.021 | AK4: 50.969 | AL4: 52.103 | AM4: 52.83 | AN4: 53.212 | AO4: 52.487 | AP4: 54.532 | AQ4: 55.005 | AR4: 55.511 | AS4: 56.225 | AT4: 57.171 | AU4: 57.81 | AV4: 58.247 | AW4: 58.553 | AX4: 58.956 | AY4: 59.708 | AZ4: 60.248 | BA4: 60.702 | BB4: 61.25 | BC4: 61.735 | BD4: 62.188 | BE4: 62.26 | BF4: 62.27 | BG4: 62.646 | BH4: 62.406 | BI4: 62.443 | BJ4: 62.941 | BK4: 61.454 | BL4: 60.417 | BM4: 65.617 | BN4: 66.035 | BO4: 66.289 | BP4: Middle East & North Africa | BQ4: Low income
A5: Africa Western and Central | B5: AFW | C5: 37.779636 | D5: 38.058973 | E5: 38.681792 | F5: 38.936918 | G5: 39.19458 | H5: 39.479784 | I5: 39.719265 | J5: 39.529359 | K5: 40.25889 | L5: 40.567814 | M5: 41.277939 | N5: 41.730102 | O5: 42.356132 | P5: 42.868104 | Q5: 43.437155 | R5: 43.967079 | S5: 44.75257 | T5: 45.362264 | U5: 45.876278 | V5: 46.328507 | W5: 46.696229 | X5: 47.075219 | Y5: 47.373942 | Z5: 47.619559 | AA5: 47.797646 | AB5: 47.944482 | AC5: 48.038163 | AD5: 48.139567 | AE5: 48.371525 | AF5: 48.496155 | AG5: 48.459467 | AH5: 48.531229 | AI5: 48.688726 | AJ5: 48.855051 | AK5: 48.859717 | AL5: 49.027301 | AM5: 49.11178 | AN5: 49.21897 | AO5: 49.45259 | AP5: 49.823913 | AQ5: 50.29817 | AR5: 50.677996 | AS5: 51.108247 | AT5: 51.578364 | AU5: 52.106342 | AV5: 52.55603 | AW5: 52.978931 | AX5: 53.482672 | AY5: 53.916483 | AZ5: 53.852486 | BA5: 54.603593 | BB5: 54.964195 | BC5: 55.292945 | BD5: 55.55511 | BE5: 55.69563 | BF5: 56.038519 | BG5: 56.392598 | BH5: 56.626622 | BI5: 57.037104 | BJ5: 57.149956 | BK5: 57.364736 | BL5: 57.362736 | BM5: 57.98785 | BN5: 58.85574 | BO5: 59.049811
A6: Angola | B6: AGO | C6: 37.933 | D6: 36.902 | E6: 37.168 | F6: 37.419 | G6: 37.704 | H6: 37.968 | I6: 38.258 | J6: 38.616 | K6: 38.968 | L6: 39.329 | M6: 39.688 | N6: 40.076 | O6: 40.469 | P6: 40.871 | Q6: 41.26 | R6: 40.817 | S6: 40.812 | T6: 41.215 | U6: 41.573 | V6: 41.913 | W6: 42.242 | X6: 42.556 | Y6: 42.857 | Z6: 41.972 | AA6: 42.245 | AB6: 42.495 | AC6: 42.739 | AD6: 40.786 | AE6: 41.471 | AF6: 41.698 | AG6: 41.854 | AH6: 43.812 | AI6: 42.267 | AJ6: 42.19 | AK6: 43.567 | AL6: 46.139 | AM6: 46.418 | AN6: 46.688 | AO6: 45.452 | AP6: 45.808 | AQ6: 46.501 | AR6: 47.032 | AS6: 47.874 | AT6: 50.218 | AU6: 51.123 | AV6: 52.13 | AW6: 52.965 | AX6: 54.2 | AY6: 55.281 | AZ6: 56.225 | BA6: 57.242 | BB6: 58.093 | BC6: 58.916 | BD6: 59.705 | BE6: 60.396 | BF6: 61.042 | BG6: 61.619 | BH6: 62.122 | BI6: 62.622 | BJ6: 63.051 | BK6: 63.116 | BL6: 62.958 | BM6: 64.246 | BN6: 64.617 | BO6: 64.805 | BP6: Sub-Saharan Africa | BQ6: Lower middle income
A7: Albania | B7: ALB | C7: 56.413 | D7: 57.488 | E7: 58.494 | F7: 59.479 | G7: 60.404 | H7: 61.273 | I7: 62.149 | J7: 62.976 | K7: 63.788 | L7: 64.538 | M7: 65.234 | N7: 65.896 | O7: 66.526 | P7: 67.107 | Q7: 67.633 | R7: 68.12 | S7: 68.57 | T7: 68.992 | U7: 69.367 | V7: 69.617 | W7: 69.903 | X7: 70.145 | Y7: 70.425 | Z7: 70.705 | AA7: 70.984 | AB7: 71.282 | AC7: 71.665 | AD7: 71.981 | AE7: 72.217 | AF7: 72.457 | AG7: 72.71 | AH7: 73.001 | AI7: 73.303 | AJ7: 73.638 | AK7: 73.837 | AL7: 74.022 | AM7: 74.113 | AN7: 73.383 | AO7: 74.357 | AP7: 74.568 | AQ7: 74.826 | AR7: 75.083 | AS7: 75.299 | AT7: 75.557 | AU7: 75.951 | AV7: 76.427 | AW7: 76.994 | AX7: 77.691 | AY7: 78.248 | AZ7: 78.509 | BA7: 78.414 | BB7: 78.303 | BC7: 78.084 | BD7: 77.995 | BE7: 78.029 | BF7: 78.358 | BG7: 78.643 | BH7: 78.9 | BI7: 79.238 | BJ7: 79.467 | BK7: 77.824 | BL7: 76.844 | BM7: 78.769 | BN7: 79.602 | BO7: 79.776 | BP7: Europe & Central Asia | BQ7: Upper middle income
A8: Andorra | B8: AND | C8: 72.094 | D8: 72.573 | E8: 72.993 | F8: 73.298 | G8: 73.624 | H8: 73.856 | I8: 74.02 | J8: 74.119 | K8: 74.22 | L8: 74.296 | M8: 74.452 | N8: 74.615 | O8: 74.864 | P8: 75.096 | Q8: 75.34 | R8: 75.567 | S8: 75.869 | T8: 76.154 | U8: 76.488 | V8: 76.819 | W8: 77.137 | X8: 77.391 | Y8: 77.617 | Z8: 77.787 | AA8: 77.916 | AB8: 78.006 | AC8: 78.107 | AD8: 78.189 | AE8: 78.364 | AF8: 78.557 | AG8: 78.961 | AH8: 79.346 | AI8: 79.794 | AJ8: 80.186 | AK8: 80.587 | AL8: 80.804 | AM8: 81.009 | AN8: 81.145 | AO8: 81.28 | AP8: 81.55 | AQ8: 81.863 | AR8: 82.162 | AS8: 82.448 | AT8: 82.718 | AU8: 82.815 | AV8: 83.086 | AW8: 83.374 | AX8: 83.632 | AY8: 83.855 | AZ8: 84.1 | BA8: 84.197 | BB8: 84.296 | BC8: 84.334 | BD8: 84.406 | BE8: 84.485 | BF8: 84.532 | BG8: 84.489 | BH8: 84.359 | BI8: 84.242 | BJ8: 84.098 | BK8: 79.418 | BL8: 82.331 | BM8: 84.016 | BN8: 84.041 | BO8: 84.188 | BP8: Europe & Central Asia | BQ8: High income
A9: Arab World | B9: ARB | C9: 44.794056 | D9: 45.545371 | E9: 45.993769 | F9: 46.979338 | G9: 47.570034 | H9: 48.117159 | I9: 48.625424 | J9: 49.092434 | K9: 49.657787 | L9: 50.148857 | M9: 50.692871 | N9: 51.318319 | O9: 51.89371 | P9: 52.30196 | Q9: 52.92555 | R9: 53.420351 | S9: 53.850649 | T9: 55.081922 | U9: 55.757128 | V9: 56.479748 | W9: 57.006353 | X9: 57.569166 | Y9: 57.870235 | Z9: 58.637607 | AA9: 59.329582 | AB9: 59.989461 | AC9: 60.918684 | AD9: 61.620809 | AE9: 61.671533 | AF9: 62.298247 | AG9: 62.755973 | AH9: 62.827507 | AI9: 63.575576 | AJ9: 64.60128 | AK9: 64.850083 | AL9: 65.202506 | AM9: 65.526889 | AN9: 65.852992 | AO9: 66.193579 | AP9: 66.549934 | AQ9: 66.8907 | AR9: 67.240617 | AS9: 67.58063 | AT9: 67.650335 | AU9: 67.733103 | AV9: 68.040502 | AW9: 68.491265 | AX9: 68.879226 | AY9: 69.258133 | AZ9: 69.706904 | BA9: 69.807322 | BB9: 69.363338 | BC9: 69.842317 | BD9: 70.192106 | BE9: 70.535067 | BF9: 70.658012 | BG9: 70.896488 | BH9: 71.112856 | BI9: 71.4313 | BJ9: 71.839893 | BK9: 70.726559 | BL9: 70.404114 | BM9: 71.876096 | BN9: 72.444678 | BO9: 72.721805
A10: United Arab Emirates | B10: ARE | C10: 50.651 | D10: 51.596 | E10: 52.546 | F10: 53.509 | G10: 54.495 | H10: 55.512 | I10: 56.572 | J10: 57.648 | K10: 58.727 | L10: 59.764 | M10: 60.78 | N10: 61.753 | O10: 62.675 | P10: 63.542 | Q10: 64.351 | R10: 65.105 | S10: 65.806 | T10: 66.471 | U10: 67.083 | V10: 67.645 | W10: 68.157 | X10: 68.622 | Y10: 69.056 | Z10: 69.448 | AA10: 69.802 | AB10: 70.123 | AC10: 70.41 | AD10: 70.623 | AE10: 70.808 | AF10: 70.96 | AG10: 71.074 | AH10: 71.144 | AI10: 71.166 | AJ10: 71.159 | AK10: 71.204 | AL10: 71.392 | AM10: 71.82 | AN10: 72.559 | AO10: 73.66 | AP10: 74.982 | AQ10: 76.347 | AR10: 77.621 | AS10: 78.721 | AT10: 79.6 | AU10: 80.272 | AV10: 80.779 | AW10: 81.155 | AX10: 81.438 | AY10: 81.591 | AZ10: 81.679 | BA10: 81.886 | BB10: 81.898 | BC10: 81.913 | BD10: 81.95 | BE10: 81.99 | BF10: 82.076 | BG10: 82.195 | BH10: 82.388 | BI10: 82.449 | BJ10: 82.596 | BK10: 81.936 | BL10: 79.083 | BM10: 80.487 | BN10: 82.909 | BO10: 83.069 | BP10: Middle East & North Africa | BQ10: High income
A11: Argentina | B11: ARG | C11: 64.242 | D11: 64.631 | E11: 64.618 | F11: 64.855 | G11: 64.816 | H11: 65.053 | I11: 65.398 | J11: 65.467 | K11: 65.234 | L11: 65.085 | M11: 65.647 | N11: 65.619 | O11: 65.953 | P11: 66.186 | Q11: 66.405 | R11: 66.965 | S11: 67.03 | T11: 67.595 | U11: 67.999 | V11: 68.434 | W11: 68.576 | X11: 68.858 | Y11: 68.973 | Z11: 69.29 | AA11: 69.353 | AB11: 69.879 | AC11: 70.281 | AD11: 70.699 | AE11: 71.097 | AF11: 71.502 | AG11: 71.615 | AH11: 72.02 | AI11: 72.096 | AJ11: 72.303 | AK11: 72.732 | AL11: 72.864 | AM11: 73.056 | AN11: 73.407 | AO11: 73.412 | AP11: 73.683 | AQ11: 73.91 | AR11: 74.154 | AS11: 74.312 | AT11: 74.307 | AU11: 74.871 | AV11: 75.231 | AW11: 75.279 | AX11: 74.783 | AY11: 75.428 | AZ11: 75.577 | BA11: 75.68 | BB11: 76.1 | BC11: 75.802 | BD11: 75.829 | BE11: 76.268 | BF11: 76.6 | BG11: 76.105 | BH11: 76.543 | BI11: 76.77 | BJ11: 76.847 | BK11: 75.878 | BL11: 73.948 | BM11: 75.806 | BN11: 77.395 | BO11: 77.543 | BP11: Latin America & Caribbean | BQ11: Upper middle income
A12: Armenia | B12: ARM | C12: 59.063 | D12: 59.494098 | E12: 59.916683 | F12: 60.328268 | G12: 60.723829 | H12: 61.099341 | I12: 61.453829 | J12: 61.784756 | K12: 62.093634 | L12: 62.379951 | M12: 62.644707 | N12: 62.888902 | O12: 63.114488 | P12: 63.330927 | Q12: 63.546756 | R12: 63.767878 | S12: 64.001488 | T12: 64.253951 | U12: 64.526195 | V12: 64.820829 | W12: 65.138561 | X12: 65.482488 | Y12: 65.850927 | Z12: 66.229244 | AA12: 66.591366 | AB12: 66.915268 | AC12: 67.178 | AD12: 67.359073 | AE12: 52.600122 | AF12: 67.518561 | AG12: 67.549366 | AH12: 67.627049 | AI12: 67.718537 | AJ12: 67.973195 | AK12: 68.271805 | AL12: 68.628488 | AM12: 69.006122 | AN12: 69.393829 | AO12: 69.799341 | AP12: 70.198951 | AQ12: 72.880488 | AR12: 72.97561 | AS12: 72.826829 | AT12: 72.826829 | AU12: 73.026829 | AV12: 73.07561 | AW12: 72.82439 | AX12: 72.873171 | AY12: 73.073171 | AZ12: 73.073171 | BA12: 73.173171 | BB12: 73.817073 | BC12: 74.119512 | BD12: 74.621951 | BE12: 74.873171 | BF12: 74.870732 | BG12: 74.868293 | BH12: 75.217073 | BI12: 75.619512 | BJ12: 76.221951 | BK12: 73.37561 | BL12: 72.278049 | BM12: 74.765854 | BN12: 77.465854 | BO12: 78.319512 | BP12: Europe & Central Asia | BQ12: Upper middle income
A13: American Samoa | B13: ASM | C13: 65.053 | D13: 65.648 | E13: 66.008 | F13: 66.161 | G13: 66.135 | H13: 65.996 | I13: 58.284 | J13: 65.807 | K13: 65.847 | L13: 66.05 | M13: 66.364 | N13: 66.77 | O13: 67.186 | P13: 67.604 | Q13: 67.95 | R13: 68.256 | S13: 68.475 | T13: 68.701 | U13: 68.881 | V13: 69.114 | W13: 69.413 | X13: 69.731 | Y13: 69.975 | Z13: 70.163 | AA13: 70.326 | AB13: 70.532 | AC13: 70.704 | AD13: 70.828 | AE13: 70.883 | AF13: 70.929 | AG13: 71.107 | AH13: 71.312 | AI13: 71.511 | AJ13: 71.54 | AK13: 71.569 | AL13: 71.565 | AM13: 71.576 | AN13: 71.606 | AO13: 71.542 | AP13: 71.484 | AQ13: 71.443 | AR13: 71.573 | AS13: 71.755 | AT13: 71.698 | AU13: 72.277 | AV13: 72.382 | AW13: 72.397 | AX13: 72.365 | AY13: 72.43 | AZ13: 70.839 | BA13: 72.587 | BB13: 72.662 | BC13: 72.709 | BD13: 72.769 | BE13: 72.687 | BF13: 72.654 | BG13: 72.64 | BH13: 72.801 | BI13: 72.794 | BJ13: 72.751 | BK13: 72.672 | BL13: 72.708 | BM13: 72.752 | BN13: 72.852 | BO13: 72.992 | BP13: East Asia & Pacific | BQ13: High income
A14: Antigua and Barbuda | B14: ATG | C14: 62.635 | D14: 63.335 | E14: 63.995 | F14: 64.697 | G14: 65.428 | H14: 66.171 | I14: 66.902 | J14: 67.586 | K14: 68.23 | L14: 68.827 | M14: 69.371 | N14: 69.861 | O14: 70.304 | P14: 70.71 | Q14: 71.095 | R14: 71.447 | S14: 71.794 | T14: 72.149 | U14: 72.5 | V14: 72.823 | W14: 73.094 | X14: 73.32 | Y14: 73.525 | Z14: 73.684 | AA14: 73.808 | AB14: 73.873 | AC14: 73.893 | AD14: 73.873 | AE14: 73.811 | AF14: 73.628 | AG14: 73.602 | AH14: 73.472 | AI14: 73.386 | AJ14: 73.39 | AK14: 73.493 | AL14: 73.576 | AM14: 73.839 | AN14: 74.045 | AO14: 74.187 | AP14: 74.456 | AQ14: 74.819 | AR14: 75.108 | AS14: 75.237 | AT14: 75.313 | AU14: 75.329 | AV14: 75.364 | AW14: 75.506 | AX14: 75.72 | AY14: 76.075 | AZ14: 76.386 | BA14: 76.701 | BB14: 77.023 | BC14: 77.1 | BD14: 77.05 | BE14: 76.912 | BF14: 76.892 | BG14: 76.968 | BH14: 77.03 | BI14: 77.132 | BJ14: 77.168 | BK14: 77.161 | BL14: 77.197 | BM14: 77.483 | BN14: 77.598 | BO14: 77.766 | BP14: Latin America & Caribbean | BQ14: High income
